<?xml version="1.0"?>
<robot xmlns:xacro="http://ros.org/wiki/xacro">


  <xacro:include filename="$(find robot_description)/urdf/barrel/barrel.gazebo.xacro"/>
  
  <xacro:macro name="barrel_v0" params="parent *joint_origin *joint_axis">
	<joint name="pitch_joint" type="continuous">
	  <!-- <xacro:insert_block name="joint_origin"/> -->
	  <origin rpy="0 3.14159 0" xyz="0 0 0" />
	  <parent link="${parent}"/>
	  <child link="pitch_link"/>
          <limit effort="15" velocity="10" lower="-3.14159" upper = "3.14159"/>
          <dynamics damping="0.00001" friction="0.01"/>
	  <xacro:insert_block name="joint_axis"/>
	</joint>

	<link name="pitch_link">
	  <visual>
		<geometry>
		  <mesh filename="package://robot_description/meshes/DAE/barrel/pole.dae"/>
		</geometry>
	  </visual>
	  <collision>
		<geometry>
		  <mesh filename="package://robot_description/meshes/STL/barrel/pole.stl"/>
		</geometry>
	  </collision>
	  <inertial>
		<origin xyz="0 0 -0.489554"/>
		<mass value="0.85955"/>
		<inertia ixx="0.07508" ixy="0" ixz="-0.0000095" iyy="0.07574" iyz="0" izz="0.0007851"/>
	  </inertial>
	</link>
  </xacro:macro>
  
</robot>

